Traceback (most recent call last):
  File "/opt/hostedtoolcache/Python/3.7.12/x64/lib/python3.7/site-packages/jupyter_cache/executors/utils.py", line 56, in single_nb_execution
    record_timing=False,
  File "/opt/hostedtoolcache/Python/3.7.12/x64/lib/python3.7/site-packages/nbclient/client.py", line 1117, in execute
    return NotebookClient(nb=nb, resources=resources, km=km, **kwargs).execute()
  File "/opt/hostedtoolcache/Python/3.7.12/x64/lib/python3.7/site-packages/nbclient/util.py", line 78, in wrapped
    return just_run(coro(*args, **kwargs))
  File "/opt/hostedtoolcache/Python/3.7.12/x64/lib/python3.7/site-packages/nbclient/util.py", line 57, in just_run
    return loop.run_until_complete(coro)
  File "/opt/hostedtoolcache/Python/3.7.12/x64/lib/python3.7/asyncio/base_events.py", line 587, in run_until_complete
    return future.result()
  File "/opt/hostedtoolcache/Python/3.7.12/x64/lib/python3.7/site-packages/nbclient/client.py", line 559, in async_execute
    cell, index, execution_count=self.code_cells_executed + 1
  File "/opt/hostedtoolcache/Python/3.7.12/x64/lib/python3.7/site-packages/nbclient/client.py", line 862, in async_execute_cell
    self._check_raise_for_error(cell, exec_reply)
  File "/opt/hostedtoolcache/Python/3.7.12/x64/lib/python3.7/site-packages/nbclient/client.py", line 765, in _check_raise_for_error
    raise CellExecutionError.from_cell_and_msg(cell, exec_reply_content)
nbclient.exceptions.CellExecutionError: An error occurred while executing the following cell:
------------------
workflows.t2smap_workflow(
    data_files,
    echo_times,
    out_dir=out_dir,
    mask=mask_file,
    prefix="sub-04570_task-rest_space-scanner",
    fittype="loglin",
    fitmode="ts",
)
------------------

[0;31m---------------------------------------------------------------------------[0m
[0;31mFileNotFoundError[0m                         Traceback (most recent call last)
[0;32m/tmp/ipykernel_1705/2204136142.py[0m in [0;36m<module>[0;34m[0m
[1;32m      6[0m     [0mprefix[0m[0;34m=[0m[0;34m"sub-04570_task-rest_space-scanner"[0m[0;34m,[0m[0;34m[0m[0;34m[0m[0m
[1;32m      7[0m     [0mfittype[0m[0;34m=[0m[0;34m"loglin"[0m[0;34m,[0m[0;34m[0m[0;34m[0m[0m
[0;32m----> 8[0;31m     [0mfitmode[0m[0;34m=[0m[0;34m"ts"[0m[0;34m,[0m[0;34m[0m[0;34m[0m[0m
[0m[1;32m      9[0m )

[0;32m/opt/hostedtoolcache/Python/3.7.12/x64/lib/python3.7/site-packages/tedana/workflows/t2smap.py[0m in [0;36mt2smap_workflow[0;34m(data, tes, out_dir, mask, prefix, convention, fittype, fitmode, combmode, debug, quiet)[0m
[1;32m    223[0m     [0mout_dir[0m [0;34m=[0m [0mop[0m[0;34m.[0m[0mabspath[0m[0;34m([0m[0mout_dir[0m[0;34m)[0m[0;34m[0m[0;34m[0m[0m
[1;32m    224[0m     [0;32mif[0m [0;32mnot[0m [0mop[0m[0;34m.[0m[0misdir[0m[0;34m([0m[0mout_dir[0m[0;34m)[0m[0;34m:[0m[0;34m[0m[0;34m[0m[0m
[0;32m--> 225[0;31m         [0mos[0m[0;34m.[0m[0mmkdir[0m[0;34m([0m[0mout_dir[0m[0;34m)[0m[0;34m[0m[0;34m[0m[0m
[0m[1;32m    226[0m [0;34m[0m[0m
[1;32m    227[0m     [0mutils[0m[0;34m.[0m[0msetup_loggers[0m[0;34m([0m[0mquiet[0m[0;34m=[0m[0mquiet[0m[0;34m,[0m [0mdebug[0m[0;34m=[0m[0mdebug[0m[0;34m)[0m[0;34m[0m[0;34m[0m[0m

[0;31mFileNotFoundError[0m: [Errno 2] No such file or directory: '/home/runner/work/multi-echo-data-analysis/multi-echo-data-analysis/data/fit'
FileNotFoundError: [Errno 2] No such file or directory: '/home/runner/work/multi-echo-data-analysis/multi-echo-data-analysis/data/fit'

