Traceback (most recent call last):
  File "/opt/hostedtoolcache/Python/3.7.12/x64/lib/python3.7/site-packages/jupyter_cache/executors/utils.py", line 56, in single_nb_execution
    record_timing=False,
  File "/opt/hostedtoolcache/Python/3.7.12/x64/lib/python3.7/site-packages/nbclient/client.py", line 1093, in execute
    return NotebookClient(nb=nb, resources=resources, km=km, **kwargs).execute()
  File "/opt/hostedtoolcache/Python/3.7.12/x64/lib/python3.7/site-packages/nbclient/util.py", line 84, in wrapped
    return just_run(coro(*args, **kwargs))
  File "/opt/hostedtoolcache/Python/3.7.12/x64/lib/python3.7/site-packages/nbclient/util.py", line 62, in just_run
    return loop.run_until_complete(coro)
  File "/opt/hostedtoolcache/Python/3.7.12/x64/lib/python3.7/asyncio/base_events.py", line 587, in run_until_complete
    return future.result()
  File "/opt/hostedtoolcache/Python/3.7.12/x64/lib/python3.7/site-packages/nbclient/client.py", line 560, in async_execute
    cell, index, execution_count=self.code_cells_executed + 1
  File "/opt/hostedtoolcache/Python/3.7.12/x64/lib/python3.7/site-packages/nbclient/client.py", line 854, in async_execute_cell
    self._check_raise_for_error(cell, exec_reply)
  File "/opt/hostedtoolcache/Python/3.7.12/x64/lib/python3.7/site-packages/nbclient/client.py", line 756, in _check_raise_for_error
    raise CellExecutionError.from_cell_and_msg(cell, exec_reply_content)
nbclient.exceptions.CellExecutionError: An error occurred while executing the following cell:
------------------
import os
from pprint import pprint

from tedana import datasets

DATA_DIR = os.path.abspath("../data")

euskalibur_dataset = datasets.fetch_euskalibur(
    n_subjects=5,
    low_resolution=False,
    data_dir=DATA_DIR,
)
pprint(euskalibur_dataset)

cambridge_dataset = datasets.fetch_cambridge(
    n_subjects=5,
    low_resolution=False,
    data_dir=DATA_DIR,
)
pprint(cambridge_dataset)
------------------

[0;31m---------------------------------------------------------------------------[0m
[0;31mImportError[0m                               Traceback (most recent call last)
[0;32m/tmp/ipykernel_1888/2827171989.py[0m in [0;36m<module>[0;34m[0m
[1;32m      2[0m [0;32mfrom[0m [0mpprint[0m [0;32mimport[0m [0mpprint[0m[0;34m[0m[0;34m[0m[0m
[1;32m      3[0m [0;34m[0m[0m
[0;32m----> 4[0;31m [0;32mfrom[0m [0mtedana[0m [0;32mimport[0m [0mdatasets[0m[0;34m[0m[0;34m[0m[0m
[0m[1;32m      5[0m [0;34m[0m[0m
[1;32m      6[0m [0mDATA_DIR[0m [0;34m=[0m [0mos[0m[0;34m.[0m[0mpath[0m[0;34m.[0m[0mabspath[0m[0;34m([0m[0;34m"../data"[0m[0;34m)[0m[0;34m[0m[0;34m[0m[0m

[0;31mImportError[0m: cannot import name 'datasets' from 'tedana' (/opt/hostedtoolcache/Python/3.7.12/x64/lib/python3.7/site-packages/tedana/__init__.py)
ImportError: cannot import name 'datasets' from 'tedana' (/opt/hostedtoolcache/Python/3.7.12/x64/lib/python3.7/site-packages/tedana/__init__.py)

