Traceback (most recent call last):
  File "/opt/hostedtoolcache/Python/3.7.12/x64/lib/python3.7/site-packages/jupyter_cache/executors/utils.py", line 56, in single_nb_execution
    record_timing=False,
  File "/opt/hostedtoolcache/Python/3.7.12/x64/lib/python3.7/site-packages/nbclient/client.py", line 1093, in execute
    return NotebookClient(nb=nb, resources=resources, km=km, **kwargs).execute()
  File "/opt/hostedtoolcache/Python/3.7.12/x64/lib/python3.7/site-packages/nbclient/util.py", line 84, in wrapped
    return just_run(coro(*args, **kwargs))
  File "/opt/hostedtoolcache/Python/3.7.12/x64/lib/python3.7/site-packages/nbclient/util.py", line 62, in just_run
    return loop.run_until_complete(coro)
  File "/opt/hostedtoolcache/Python/3.7.12/x64/lib/python3.7/asyncio/base_events.py", line 587, in run_until_complete
    return future.result()
  File "/opt/hostedtoolcache/Python/3.7.12/x64/lib/python3.7/site-packages/nbclient/client.py", line 560, in async_execute
    cell, index, execution_count=self.code_cells_executed + 1
  File "/opt/hostedtoolcache/Python/3.7.12/x64/lib/python3.7/site-packages/nbclient/client.py", line 854, in async_execute_cell
    self._check_raise_for_error(cell, exec_reply)
  File "/opt/hostedtoolcache/Python/3.7.12/x64/lib/python3.7/site-packages/nbclient/client.py", line 756, in _check_raise_for_error
    raise CellExecutionError.from_cell_and_msg(cell, exec_reply_content)
nbclient.exceptions.CellExecutionError: An error occurred while executing the following cell:
------------------
fig, axes = plt.subplots(n_echoes, sharex=True, sharey=False, figsize=(14, 6))
for i_echo in range(n_echoes):
    axes[i_echo].plot(ts[i_echo], color=pal[i_echo])
    axes[i_echo].set_ylabel(f"{echo_times[i_echo]}ms", rotation=0, va="center", ha="right", fontsize=14)
    axes[i_echo].set_yticks([])
    axes[i_echo].set_xticks([])

axes[-1].set_xlabel("Time", fontsize=16)
axes[-1].set_xlim(0, len(ts[i_echo])-1)
fig.tight_layout()
glue("fig_echo_timeseries", fig, display=False)
------------------

[0;31m---------------------------------------------------------------------------[0m
[0;31mNameError[0m                                 Traceback (most recent call last)
[0;32m/tmp/ipykernel_2401/1601315681.py[0m in [0;36m<module>[0;34m[0m
[1;32m      9[0m [0maxes[0m[0;34m[[0m[0;34m-[0m[0;36m1[0m[0;34m][0m[0;34m.[0m[0mset_xlim[0m[0;34m([0m[0;36m0[0m[0;34m,[0m [0mlen[0m[0;34m([0m[0mts[0m[0;34m[[0m[0mi_echo[0m[0;34m][0m[0;34m)[0m[0;34m-[0m[0;36m1[0m[0;34m)[0m[0;34m[0m[0;34m[0m[0m
[1;32m     10[0m [0mfig[0m[0;34m.[0m[0mtight_layout[0m[0;34m([0m[0;34m)[0m[0;34m[0m[0;34m[0m[0m
[0;32m---> 11[0;31m [0mglue[0m[0;34m([0m[0;34m"fig_echo_timeseries"[0m[0;34m,[0m [0mfig[0m[0;34m,[0m [0mdisplay[0m[0;34m=[0m[0;32mFalse[0m[0;34m)[0m[0;34m[0m[0;34m[0m[0m
[0m
[0;31mNameError[0m: name 'glue' is not defined
NameError: name 'glue' is not defined

