Traceback (most recent call last):
  File "/opt/hostedtoolcache/Python/3.7.12/x64/lib/python3.7/site-packages/jupyter_cache/executors/utils.py", line 56, in single_nb_execution
    record_timing=False,
  File "/opt/hostedtoolcache/Python/3.7.12/x64/lib/python3.7/site-packages/nbclient/client.py", line 1093, in execute
    return NotebookClient(nb=nb, resources=resources, km=km, **kwargs).execute()
  File "/opt/hostedtoolcache/Python/3.7.12/x64/lib/python3.7/site-packages/nbclient/util.py", line 84, in wrapped
    return just_run(coro(*args, **kwargs))
  File "/opt/hostedtoolcache/Python/3.7.12/x64/lib/python3.7/site-packages/nbclient/util.py", line 62, in just_run
    return loop.run_until_complete(coro)
  File "/opt/hostedtoolcache/Python/3.7.12/x64/lib/python3.7/asyncio/base_events.py", line 587, in run_until_complete
    return future.result()
  File "/opt/hostedtoolcache/Python/3.7.12/x64/lib/python3.7/site-packages/nbclient/client.py", line 560, in async_execute
    cell, index, execution_count=self.code_cells_executed + 1
  File "/opt/hostedtoolcache/Python/3.7.12/x64/lib/python3.7/site-packages/nbclient/client.py", line 854, in async_execute_cell
    self._check_raise_for_error(cell, exec_reply)
  File "/opt/hostedtoolcache/Python/3.7.12/x64/lib/python3.7/site-packages/nbclient/client.py", line 756, in _check_raise_for_error
    raise CellExecutionError.from_cell_and_msg(cell, exec_reply_content)
nbclient.exceptions.CellExecutionError: An error occurred while executing the following cell:
------------------
func_dir = os.path.join(data_path, "sub-04570/func/")
data_files = [
    os.path.join(func_dir, "sub-04570_task-rest_echo-1_space-scanner_desc-partialPreproc_bold.nii.gz"),
    os.path.join(func_dir, "sub-04570_task-rest_echo-2_space-scanner_desc-partialPreproc_bold.nii.gz"),
    os.path.join(func_dir, "sub-04570_task-rest_echo-3_space-scanner_desc-partialPreproc_bold.nii.gz"),
    os.path.join(func_dir, "sub-04570_task-rest_echo-4_space-scanner_desc-partialPreproc_bold.nii.gz"),
]
echo_times = [12., 28., 44., 60.]

img = image.index_img(data_files[0], 0)
data = img.get_fdata()
vmax = np.max(data)
idx = np.vstack(np.where(data > 1000))

min_x, min_y, min_z = np.min(idx, axis=1)
max_x, max_y, max_z = np.max(idx, axis=1)

imgs = []
for f in data_files:
    img = image.index_img(f, 0)
    data = img.get_fdata()
    data = data[min_x:max_x, min_y:max_y, min_z:max_z]
    img = nib.Nifti1Image(data, img.affine, img.header)
    imgs.append(img)
------------------

[0;31m---------------------------------------------------------------------------[0m
[0;31mNameError[0m                                 Traceback (most recent call last)
[0;32m/tmp/ipykernel_2111/4032045990.py[0m in [0;36m<module>[0;34m[0m
[1;32m      8[0m [0mecho_times[0m [0;34m=[0m [0;34m[[0m[0;36m12.[0m[0;34m,[0m [0;36m28.[0m[0;34m,[0m [0;36m44.[0m[0;34m,[0m [0;36m60.[0m[0;34m][0m[0;34m[0m[0;34m[0m[0m
[1;32m      9[0m [0;34m[0m[0m
[0;32m---> 10[0;31m [0mimg[0m [0;34m=[0m [0mimage[0m[0;34m.[0m[0mindex_img[0m[0;34m([0m[0mdata_files[0m[0;34m[[0m[0;36m0[0m[0;34m][0m[0;34m,[0m [0;36m0[0m[0;34m)[0m[0;34m[0m[0;34m[0m[0m
[0m[1;32m     11[0m [0mdata[0m [0;34m=[0m [0mimg[0m[0;34m.[0m[0mget_fdata[0m[0;34m([0m[0;34m)[0m[0;34m[0m[0;34m[0m[0m
[1;32m     12[0m [0mvmax[0m [0;34m=[0m [0mnp[0m[0;34m.[0m[0mmax[0m[0;34m([0m[0mdata[0m[0;34m)[0m[0;34m[0m[0;34m[0m[0m

[0;31mNameError[0m: name 'image' is not defined
NameError: name 'image' is not defined

