Traceback (most recent call last):
  File "/opt/hostedtoolcache/Python/3.7.12/x64/lib/python3.7/site-packages/jupyter_cache/executors/utils.py", line 56, in single_nb_execution
    record_timing=False,
  File "/opt/hostedtoolcache/Python/3.7.12/x64/lib/python3.7/site-packages/nbclient/client.py", line 1093, in execute
    return NotebookClient(nb=nb, resources=resources, km=km, **kwargs).execute()
  File "/opt/hostedtoolcache/Python/3.7.12/x64/lib/python3.7/site-packages/nbclient/util.py", line 84, in wrapped
    return just_run(coro(*args, **kwargs))
  File "/opt/hostedtoolcache/Python/3.7.12/x64/lib/python3.7/site-packages/nbclient/util.py", line 62, in just_run
    return loop.run_until_complete(coro)
  File "/opt/hostedtoolcache/Python/3.7.12/x64/lib/python3.7/asyncio/base_events.py", line 587, in run_until_complete
    return future.result()
  File "/opt/hostedtoolcache/Python/3.7.12/x64/lib/python3.7/site-packages/nbclient/client.py", line 560, in async_execute
    cell, index, execution_count=self.code_cells_executed + 1
  File "/opt/hostedtoolcache/Python/3.7.12/x64/lib/python3.7/site-packages/nbclient/client.py", line 854, in async_execute_cell
    self._check_raise_for_error(cell, exec_reply)
  File "/opt/hostedtoolcache/Python/3.7.12/x64/lib/python3.7/site-packages/nbclient/client.py", line 756, in _check_raise_for_error
    raise CellExecutionError.from_cell_and_msg(cell, exec_reply_content)
nbclient.exceptions.CellExecutionError: An error occurred while executing the following cell:
------------------
import os

import numpy as np
import matplotlib.pyplot as plt
import seaborn as sns
from scipy import signal, stats
from nilearn.glm import first_level
from repo2data.repo2data import Repo2Data

from book_utils import pred_bold_signal

# Install the data if running locally, or point to cached data if running on neurolibre
DATA_REQ_FILE = os.path.join("../binder/data_requirement.json")

# Download data
repo2data = Repo2Data(DATA_REQ_FILE)
data_path = repo2data.install()
data_path = os.path.abspath(os.path.join(data_path[0], "data"))

out_dir = os.path.join(data_path, "te-dependence")
os.makedirs(out_dir, exist_ok=True)
------------------

[0;31m---------------------------------------------------------------------------[0m
[0;31mImportError[0m                               Traceback (most recent call last)
[0;32m/tmp/ipykernel_2387/385783001.py[0m in [0;36m<module>[0;34m[0m
[1;32m      8[0m [0;32mfrom[0m [0mrepo2data[0m[0;34m.[0m[0mrepo2data[0m [0;32mimport[0m [0mRepo2Data[0m[0;34m[0m[0;34m[0m[0m
[1;32m      9[0m [0;34m[0m[0m
[0;32m---> 10[0;31m [0;32mfrom[0m [0mbook_utils[0m [0;32mimport[0m [0mpred_bold_signal[0m[0;34m[0m[0;34m[0m[0m
[0m[1;32m     11[0m [0;34m[0m[0m
[1;32m     12[0m [0;31m# Install the data if running locally, or point to cached data if running on neurolibre[0m[0;34m[0m[0;34m[0m[0;34m[0m[0m

[0;31mImportError[0m: cannot import name 'pred_bold_signal' from 'book_utils' (/home/runner/work/multi-echo-data-analysis/multi-echo-data-analysis/content/book_utils.py)
ImportError: cannot import name 'pred_bold_signal' from 'book_utils' (/home/runner/work/multi-echo-data-analysis/multi-echo-data-analysis/content/book_utils.py)

