Traceback (most recent call last):
  File "/opt/hostedtoolcache/Python/3.7.12/x64/lib/python3.7/site-packages/jupyter_cache/executors/utils.py", line 56, in single_nb_execution
    record_timing=False,
  File "/opt/hostedtoolcache/Python/3.7.12/x64/lib/python3.7/site-packages/nbclient/client.py", line 1117, in execute
    return NotebookClient(nb=nb, resources=resources, km=km, **kwargs).execute()
  File "/opt/hostedtoolcache/Python/3.7.12/x64/lib/python3.7/site-packages/nbclient/util.py", line 78, in wrapped
    return just_run(coro(*args, **kwargs))
  File "/opt/hostedtoolcache/Python/3.7.12/x64/lib/python3.7/site-packages/nbclient/util.py", line 57, in just_run
    return loop.run_until_complete(coro)
  File "/opt/hostedtoolcache/Python/3.7.12/x64/lib/python3.7/asyncio/base_events.py", line 587, in run_until_complete
    return future.result()
  File "/opt/hostedtoolcache/Python/3.7.12/x64/lib/python3.7/site-packages/nbclient/client.py", line 559, in async_execute
    cell, index, execution_count=self.code_cells_executed + 1
  File "/opt/hostedtoolcache/Python/3.7.12/x64/lib/python3.7/site-packages/nbclient/client.py", line 862, in async_execute_cell
    self._check_raise_for_error(cell, exec_reply)
  File "/opt/hostedtoolcache/Python/3.7.12/x64/lib/python3.7/site-packages/nbclient/client.py", line 765, in _check_raise_for_error
    raise CellExecutionError.from_cell_and_msg(cell, exec_reply_content)
nbclient.exceptions.CellExecutionError: An error occurred while executing the following cell:
------------------
tedana_dir = os.path.abspath("../data/tedana-main")
figures_dir = os.path.join(tedana_dir, "figures")
figures_dir = os.path.relpath(figures_dir, os.getcwd())
print(figures_dir)

report = os.path.join(tedana_dir, "tedana_report.html")
with open(report, "r") as fo:
    report_data = fo.read()

report_data = report_data.replace("./figures", figures_dir)
------------------

[0;31m---------------------------------------------------------------------------[0m
[0;31mFileNotFoundError[0m                         Traceback (most recent call last)
[0;32m/tmp/ipykernel_2318/3729724842.py[0m in [0;36m<module>[0;34m[0m
[1;32m      5[0m [0;34m[0m[0m
[1;32m      6[0m [0mreport[0m [0;34m=[0m [0mos[0m[0;34m.[0m[0mpath[0m[0;34m.[0m[0mjoin[0m[0;34m([0m[0mtedana_dir[0m[0;34m,[0m [0;34m"tedana_report.html"[0m[0;34m)[0m[0;34m[0m[0;34m[0m[0m
[0;32m----> 7[0;31m [0;32mwith[0m [0mopen[0m[0;34m([0m[0mreport[0m[0;34m,[0m [0;34m"r"[0m[0;34m)[0m [0;32mas[0m [0mfo[0m[0;34m:[0m[0;34m[0m[0;34m[0m[0m
[0m[1;32m      8[0m     [0mreport_data[0m [0;34m=[0m [0mfo[0m[0;34m.[0m[0mread[0m[0;34m([0m[0;34m)[0m[0;34m[0m[0;34m[0m[0m
[1;32m      9[0m [0;34m[0m[0m

[0;31mFileNotFoundError[0m: [Errno 2] No such file or directory: '/home/runner/work/multi-echo-data-analysis/multi-echo-data-analysis/data/tedana-main/tedana_report.html'
FileNotFoundError: [Errno 2] No such file or directory: '/home/runner/work/multi-echo-data-analysis/multi-echo-data-analysis/data/tedana-main/tedana_report.html'

