Traceback (most recent call last):
  File "/opt/hostedtoolcache/Python/3.12.11/x64/lib/python3.12/site-packages/jupyter_cache/executors/utils.py", line 58, in single_nb_execution
    executenb(
  File "/opt/hostedtoolcache/Python/3.12.11/x64/lib/python3.12/site-packages/nbclient/client.py", line 1319, in execute
    return NotebookClient(nb=nb, resources=resources, km=km, **kwargs).execute()
           ^^^^^^^^^^^^^^^^^^^^^^^^^^^^^^^^^^^^^^^^^^^^^^^^^^^^^^^^^^^^^^^^^^^^^
  File "/opt/hostedtoolcache/Python/3.12.11/x64/lib/python3.12/site-packages/jupyter_core/utils/__init__.py", line 165, in wrapped
    return loop.run_until_complete(inner)
           ^^^^^^^^^^^^^^^^^^^^^^^^^^^^^^
  File "/opt/hostedtoolcache/Python/3.12.11/x64/lib/python3.12/asyncio/base_events.py", line 691, in run_until_complete
    return future.result()
           ^^^^^^^^^^^^^^^
  File "/opt/hostedtoolcache/Python/3.12.11/x64/lib/python3.12/site-packages/nbclient/client.py", line 709, in async_execute
    await self.async_execute_cell(
  File "/opt/hostedtoolcache/Python/3.12.11/x64/lib/python3.12/site-packages/nbclient/client.py", line 1062, in async_execute_cell
    await self._check_raise_for_error(cell, cell_index, exec_reply)
  File "/opt/hostedtoolcache/Python/3.12.11/x64/lib/python3.12/site-packages/nbclient/client.py", line 918, in _check_raise_for_error
    raise CellExecutionError.from_cell_and_msg(cell, exec_reply_content)
nbclient.exceptions.CellExecutionError: An error occurred while executing the following cell:
------------------
workflows.t2smap_workflow(
    data_files,
    echo_times,
    out_dir=out_dir,
    mask=mask_file,
    prefix="sub-24053_ses-1_task-rat_rec-nordic_dir-PA_run-01_",
    fittype="loglin",
    fitmode="ts",
    overwrite=True,
)
------------------


[31m---------------------------------------------------------------------------[39m
[31mFileNotFoundError[39m                         Traceback (most recent call last)
[36mCell[39m[36m [39m[32mIn[3][39m[32m, line 1[39m
[32m----> [39m[32m1[39m [43mworkflows[49m[43m.[49m[43mt2smap_workflow[49m[43m([49m
[32m      2[39m [43m    [49m[43mdata_files[49m[43m,[49m
[32m      3[39m [43m    [49m[43mecho_times[49m[43m,[49m
[32m      4[39m [43m    [49m[43mout_dir[49m[43m=[49m[43mout_dir[49m[43m,[49m
[32m      5[39m [43m    [49m[43mmask[49m[43m=[49m[43mmask_file[49m[43m,[49m
[32m      6[39m [43m    [49m[43mprefix[49m[43m=[49m[33;43m"[39;49m[33;43msub-24053_ses-1_task-rat_rec-nordic_dir-PA_run-01_[39;49m[33;43m"[39;49m[43m,[49m
[32m      7[39m [43m    [49m[43mfittype[49m[43m=[49m[33;43m"[39;49m[33;43mloglin[39;49m[33;43m"[39;49m[43m,[49m
[32m      8[39m [43m    [49m[43mfitmode[49m[43m=[49m[33;43m"[39;49m[33;43mts[39;49m[33;43m"[39;49m[43m,[49m
[32m      9[39m [43m    [49m[43moverwrite[49m[43m=[49m[38;5;28;43;01mTrue[39;49;00m[43m,[49m
[32m     10[39m [43m)[49m

[36mFile [39m[32m/opt/hostedtoolcache/Python/3.12.11/x64/lib/python3.12/site-packages/tedana/workflows/t2smap.py:322[39m, in [36mt2smap_workflow[39m[34m(data, tes, n_independent_echos, out_dir, mask, prefix, convention, dummy_scans, exclude, masktype, fittype, fitmode, combmode, debug, verbose, quiet, overwrite, t2smap_command)[39m
[32m    320[39m out_dir = op.abspath(out_dir)
[32m    321[39m [38;5;28;01mif[39;00m [38;5;129;01mnot[39;00m op.isdir(out_dir):
[32m--> [39m[32m322[39m     [43mos[49m[43m.[49m[43mmkdir[49m[43m([49m[43mout_dir[49m[43m)[49m
[32m    324[39m [38;5;66;03m# Parse exclude parameter[39;00m
[32m    325[39m exclude_idx = parse_volume_indices(exclude)

[31mFileNotFoundError[39m: [Errno 2] No such file or directory: '/home/runner/work/multi-echo-data-analysis/multi-echo-data-analysis/DATA/fit'

