Traceback (most recent call last):
  File "/opt/hostedtoolcache/Python/3.10.18/x64/lib/python3.10/site-packages/jupyter_core/utils/__init__.py", line 154, in wrapped
    asyncio.get_running_loop()
RuntimeError: no running event loop

During handling of the above exception, another exception occurred:

Traceback (most recent call last):
  File "/opt/hostedtoolcache/Python/3.10.18/x64/lib/python3.10/site-packages/jupyter_cache/executors/utils.py", line 58, in single_nb_execution
    executenb(
  File "/opt/hostedtoolcache/Python/3.10.18/x64/lib/python3.10/site-packages/nbclient/client.py", line 1319, in execute
    return NotebookClient(nb=nb, resources=resources, km=km, **kwargs).execute()
  File "/opt/hostedtoolcache/Python/3.10.18/x64/lib/python3.10/site-packages/jupyter_core/utils/__init__.py", line 158, in wrapped
    return loop.run_until_complete(inner)
  File "/opt/hostedtoolcache/Python/3.10.18/x64/lib/python3.10/asyncio/base_events.py", line 649, in run_until_complete
    return future.result()
  File "/opt/hostedtoolcache/Python/3.10.18/x64/lib/python3.10/site-packages/nbclient/client.py", line 709, in async_execute
    await self.async_execute_cell(
  File "/opt/hostedtoolcache/Python/3.10.18/x64/lib/python3.10/site-packages/nbclient/client.py", line 1062, in async_execute_cell
    await self._check_raise_for_error(cell, cell_index, exec_reply)
  File "/opt/hostedtoolcache/Python/3.10.18/x64/lib/python3.10/site-packages/nbclient/client.py", line 918, in _check_raise_for_error
    raise CellExecutionError.from_cell_and_msg(cell, exec_reply_content)
nbclient.exceptions.CellExecutionError: An error occurred while executing the following cell:
------------------
from pySPFM import pySPFM

pySPFM.pySPFM(
    data_fn=data_files,
    mask_fn=mask_file,
    output_filename=os.path.join(out_dir, "out"),
    tr=2.47,
    out_dir=out_dir,
    te=echo_times,
)
------------------


[0;31m---------------------------------------------------------------------------[0m
[0;31mImportError[0m                               Traceback (most recent call last)
Cell [0;32mIn[3], line 1[0m
[0;32m----> 1[0m [38;5;28;01mfrom[39;00m[38;5;250m [39m[38;5;21;01mpySPFM[39;00m[38;5;250m [39m[38;5;28;01mimport[39;00m pySPFM
[1;32m      3[0m pySPFM[38;5;241m.[39mpySPFM(
[1;32m      4[0m     data_fn[38;5;241m=[39mdata_files,
[1;32m      5[0m     mask_fn[38;5;241m=[39mmask_file,
[0;32m   (...)[0m
[1;32m      9[0m     te[38;5;241m=[39mecho_times,
[1;32m     10[0m )

[0;31mImportError[0m: cannot import name 'pySPFM' from 'pySPFM' (/opt/hostedtoolcache/Python/3.10.18/x64/lib/python3.10/site-packages/pySPFM/__init__.py)

